Workbook
Name MmExcelLinker_62BC691A_8B18_47E7_A711_AF63CD12CBD1: #REF!
Name StudentID: #REF!

Sheet Timeline
A1: TRƯỜNG ĐẠI HỌC VĂN LANG
A2: KHOA CÔNG NGHỆ THÔNG TIN
A3: KẾ HOẠCH VÀ QUY TRÌNH THỰC HIỆN (71ITGR40106 - ĐỒ ÁN TỐT NGHIỆP - NGÀNH CÔNG NGHỆ THÔNG TIN)
A4: HỌC KỲ 02, NĂM HỌC 2025-2026
T5: KHÓA 28
B7: Thời gian chuẩn bị | D7: 3 tuần (05/1/2026-24/1/2026)
B8: Tổng số tuần nhóm sinh viên thực hiện | D8: 15 tuần (26/1/2026 -> 30/5/2026)
B9: Thời gian báo cáo và nộp điểm | D9: 3 tuần (01/6/2026 -> 20/6/2026)
B10: Số lượng sinh viên (dự kiến) | D10: 100
A12: TT | B12: GIAI ĐOẠN | C12: CÔNG VIỆC | D12: NGƯỜI THỰC HIỆN | E12: SỐ TUẦN | F12: 01/2026 | J12: 2/2026 | N12: 3/2026 | R12: 4/2026 | W12: 5/2026 | AA12: 6/2026
F13: 5-10/1 | G13: 12-17/1 | H13: 19-24/1 | I13: 26/1-1/2 | J13: 2-8/2 | K13: 9-14/2 | L13: 16-21/2 | M13: 23-28/2 | N13: 2-7/3 | O13: 9-14/3 | P13: 16-21/3 | Q13: 23-28/3 | R13: 30/3-4/4 | S13: 6-11/4 | T13: 13-18/4 | U13: 20-25/4 | V13: 27/4-2/5 | W13: 4-9/5 | X13: 11-16/5 | Y13: 18-23/5 | Z13: 25-30/5 | AA13: 1-6/6 | AB13: 8-13/6 | AC13: 15-20/6
A14: 1 | B14: Chuẩn bị | C14: Thu thập và chuẩn bị yêu cầu đề tài từ các giảng viên | D14: Thầy/Cô | E14: 1
A15: 2 | C15: Đăng ký thực hiện KLTN | D15: Sinh viên | E15: 1
A16: 3 | C16: Duyệt đăng ký của sinh viên | D16: Bộ môn | E16: 1
A17: 4 | C17: Công bố danh sách sinh viên đủ điều kiện và đề tài sẵn có để sinh viên chọn | D17: Bộ môn | E17: 1
A18: 5 | C18: Đăng ký đề tài | D18: Sinh viên | E18: 1
A19: 6 | C19: Công bố danh sách sinh viên và đề tài đã được chọn cùng với thông tin GVHD | D19: Bộ môn | E19: 1
A20: 7 | B20: Thực hiện | C20: Liên lạc với Mentor và triển khai thực hiện KLTN, nộp Đơn giấy xin đăng ký thực hiện có chữ ký sống về cho Khoa. | D20: Sinh viên, Mentor | E20: 1
A21: 8 | C21: Thực hiện và nộp Đề cương KLTN cho bộ môn | D21: Sinh viên, Mentor | E21: 2
A22: 9 | C22: Phê duyệt Đề cương KLTN, nếu đề cương được duyệt Khoa sẽ gửi danh sách cho Phòng Đào tạo đăng ký môn, lúc đó sinh viên đóng học phí. | D22: Bộ môn | E22: 1
A23: 10 | C23: Thực hiện Chỉnh sửa Đề cương KLTN theo góp ý | D23: Sinh viên, Mentor | E23: 1
A24: 11 | C24: Thực hiện tiếp tục KLTN dưới sự hướng dẫn của Mentor | D24: Sinh viên, Mentor | E24: 4
A25: 12 | B25: Báo cáo | C25: Báo cáo giữa kỳ trình bày tiến độ thực hiện KLTN | D25: Sinh viên, Hội đồng | E25: 1
A26: 13 | C26: Chỉnh sửa theo góp ý của Hội đồng và tiếp tục thực hiện KLTN | D26: Sinh viên, Mentor | E26: 1
A27: 14 | C27: Hoàn thiện Báo cáo KLTN (bản nháp) và gửi Mentor Review nhận xét có cho ra Báo cáo hay không | D27: Sinh viên, Mentor | E27: 1
A28: 15 | C28: Review và góp ý, nhận xét để sinh viên chỉnh sửa Báo cáo KLTN | D28: Sinh viên, Mentor | E28: 1
A29: 16 | C29: Nộp 1 bản Báo cáo KLTN(bản chính) cho bộ môn lập Hội đồng báo cáo | D29: Sinh viên, Mentor | E29: 1
A30: 17 | C30: Chuẩn bị Bảo vệ KLTN trước Hội đồng | D30: Mentor, Sinh viên | E30: 1
A31: 18 | C31: Bảo vệ và Hội đồng chấm điểm và nhận xét, tổng kết | D31: Sinh viên, Hội đồng, Mentor | E31: 1
A32: 19 | C32: Gửi điểm tổng kết và góp ý của Hội đồng cho sinh viên | D32: Khoa | E32: 1
A33: 20 | B33: Hoàn thiện | C33: Chỉnh sửa theo góp ý của Hội đồng và làm file xác nhận những nội dung chỉnh sửa | D33: Sinh viên | E33: 1
A34: 21 | C34: Chấm điểm sinh viên dựa trên những gì sinh viên đã làm và chỉnh sửa | D34: Mentor | E34: 1
A35: 22 | C35: Nộp 1 bản Báo cáo sau cùng + 1 Phiếu xác nhận chỉnh sửa + 1 Phiếu chấm điểm GVHD cho Khoa | D35: Sinh viên | E35: 1
A36: 23 | C36: Tổng kết điểm, nộp điểm tổng kết cho phòng khảo thí và công bố cho sinh viên | D36: Khoa | E36: 1
P38: TP. Hồ Chí Minh, ngày 28 tháng 01 năm 2026
P39: Người lập danh sách
Q42: LÝ THỊ HUYỀN CHÂU

Sheet GVHD
A1: TRƯỜNG ĐẠI HỌC VĂN LANG
A2: KHOA CÔNG NGHỆ THÔNG TIN
A4: DANH SÁCH GIẢNG VIÊN HƯỚNG DẪN ĐỒ ÁN TỐT NGHIỆP
A5: KHOÁ 28 NGÀNH CÔNG NGHỆ THÔNG TIN - CHƯƠNG TRÌNH ĐẶC BIỆT
A8: STT | B8: Họ và tên | C8: Số SV HD | D8: Email
A9: 1 | B9: Nguyễn Trương Khang | C9: 1 | D9: khang.nt@vlu.edu.vn
A10: 2 | B10: Nguyễn Đắc Quỳnh Mi | C10: 1 | D10: mi.ndq@vlu.edu.vn
A11: 3 | B11: Nguyễn Trí Hải | C11: 1 | D11: hai.nguyentri@vlu.edu.vn
A12: 4 | B12: Nguyễn Thanh Huy | C12: 1 | D12: huy.nt@vlu.edu.vn
A13: 5 | B13: Võ Xuân Thanh | C13: 1 | D13: thanh.vx@vlu.edu.vn
A14: 6 | B14: PGS. TS. Đặng Trần Khánh | C14: 1 | D14: khanh.dt@vlu.edu.vn
C16: 6
D17: TP. Hồ Chí Minh, ngày 07 tháng 01 năm 2026
D18: Người lập danh sách
D22: ThS. Lý Thị Huyền Châu

Sheet Sheet2
B1: Q172370 | C1: 1
B2: Q174263 | C2: 1
B3: Q17K374 | C3: 1
B4: Q17M428 | C4: 1
B5: Q17K360 | C5: 1
B6: Q17L969 | C6: 1
B7: Q175107 | C7: 1
B8: Q170582 | C8: 1
B9: Q176067 | C9: 1
B10: Q175747 | C10: 1
B11: Q170578 | C11: 1
B12: Q17K861 | C12: 1
... B24: Q177801 | C24: 1

Sheet THEORY (2)
A1: VAN LANG UNIVERSITY
A2: FACULTY OF INFORMATION TECHNOLOGY
A3: THEORY TEST (25%)
A4: SEMESTER 02 (2015-2016)
A5: - Course Name : Database
A6: - Instructer Name : Ly Thi Huyen Chau
A7: - Instructer Email : lythihuyenchau@vanlanguni.edu.vn
A8: - Location/Organization : VAN LANG University, Ho Chi Minh City, Viet Nam
A9: - Date of Course : Jan 2016 | M9: K20T
A10: - Duration : 15 weeks
B11: Note: | C11: - The same article: 0 point
A14: No | B14: ID | C14: FULL NAME | E14: SESSION DOB | F14: Ques 1: (1.5p) | H14: Ques 2: (1.5p) | I14: Ques 3: Data Normalization (4.0p) | K14: Ques 4: Relational Algebra (3.0p) | M14: Point - | N14: SUM | O14: SCORE
F15: Vocabulary | G15: Theory | H15: Database Schema | I15: Key (1.5p) | J15: Decomposition (2.5p) | K15: Calculate (1.5p) | L15: Language (1.5p)
A16: 1 | B16: T144296 | C16: NGUYỄN HOÀNG HOÀI | D16: ANH | E16: 24/01/96 | F16: 0.4 | G16: 0.5 | H16: 1.35 | I16: 1 | K16: 0.2 | N16: =SUM(F16:L16)-M16 -> 3.45 | O16: =IF(N16>10,10,ROUND(N16,0)) -> 3
A17: 2 | B17: T144647 | C17: LÊ THỊ DIỄM | D17: CA | E17: 28/02/96 | F17: 0.3 | G17: 0.5 | H17: 0.9 | I17: 1.5 | J17: 0.8 | N17: =SUM(F17:L17)-M17 -> 4 | O17: =IF(N17>10,10,ROUND(N17,0)) -> 4
A18: 3 | B18: T143054 | C18: PHẠM PHÚ | D18: CHƯƠNG | E18: 19/04/93 | F18: 0.3 | G18: 0.5 | H18: 1.35 | I18: 1.25 | J18: 2.5 | N18: =SUM(F18:L18)-M18 -> 5.9 | O18: =IF(N18>10,10,ROUND(N18,0)) -> 6
A19: 4 | B19: T137330 | C19: LÊ MINH | D19: ĐỨC | E19: 15/08/93 | F19: 0.2 | H19: 1.2 | I19: 1.25 | J19: 1.6 | K19: 0.4 | N19: =SUM(F19:L19)-M19 -> 4.65 | O19: =IF(N19>10,10,ROUND(N19,0)) -> 5
A20: 5 | B20: T144009 | C20: NGUYỄN ĐĂNG ĐẠI | D20: HIỆP | E20: 14/08/96 | F20: 0.2 | G20: 0.25 | I20: 1 | J20: 1.6 | K20: 0.5 | N20: =SUM(F20:L20)-M20 -> 3.55 | O20: =IF(N20>10,10,ROUND(N20,0)) -> 4
A21: 6 | B21: T146330 | C21: TRẦN TRUNG | D21: HIẾU | E21: 03/10/96 | N21: =SUM(F21:L21)-M21 -> 0 | O21: =IF(N21>10,10,ROUND(N21,0)) -> 0
A22: 7 | B22: T143334 | C22: TRẦN TẤN | D22: HIẾU | E22: 22/08/96 | F22: 0 | G22: 0 | H22: 1.2 | I22: 1 | J22: 0 | K22: 1.5 | L22: 0 | N22: =SUM(F22:L22)-M22 -> 3.7 | O22: =IF(N22>10,10,ROUND(N22,0)) -> 4
A23: 8 | B23: T146150 | C23: DƯƠNG MINH | D23: HIẾU | E23: 31/03/96 | L23: 0.3 | N23: =SUM(F23:L23)-M23 -> 0.3 | O23: =IF(N23>10,10,ROUND(N23,0)) -> 0
A24: 9 | B24: T143639 | C24: HÀ NGỌC | D24: HƯNG | E24: 20/02/96 | L24: 0.3 | N24: =SUM(F24:L24)-M24 -> 0.3 | O24: =IF(N24>10,10,ROUND(N24,0)) -> 0
A25: 10 | B25: T143324 | C25: NGUYỄN CAO | D25: LÂM | E25: 02/05/96 | N25: =SUM(F25:L25)-M25 -> 0 | O25: =IF(N25>10,10,ROUND(N25,0)) -> 0
A26: 11 | B26: T143662 | C26: THÂN DUY | D26: LINH | E26: 01/04/96 | N26: =SUM(F26:L26)-M26 -> 0 | O26: =IF(N26>10,10,ROUND(N26,0)) -> 0
A27: 12 | B27: T140026 | C27: NGUYỄN VĂN ĐỨC | D27: LINH | E27: 13/09/94 | N27: =SUM(F27:L27)-M27 -> 0 | O27: =IF(N27>10,10,ROUND(N27,0)) -> 0
A28: 13 | B28: T142772 | C28: MAI BÁ | D28: LỘC | E28: 02/01/96 | N28: =SUM(F28:L28)-M28 -> 0 | O28: =IF(N28>10,10,ROUND(N28,0)) -> 0
A29: 14 | B29: T143407 | C29: NGUYỄN THANH | D29: LONG | E29: 28/04/96 | N29: =SUM(F29:L29)-M29 -> 0 | O29: =IF(N29>10,10,ROUND(N29,0)) -> 0
A30: 15 | B30: T144054 | C30: NGUYỄN HỮU | D30: LUÂN | E30: 05/09/96 | L30: 0.3 | N30: =SUM(F30:L30)-M30 -> 0.3 | O30: =IF(N30>10,10,ROUND(N30,0)) -> 0
A31: 16 | B31: T145181 | C31: DƯƠNG THÀNH CÔNG | D31: LÝ | E31: 26/08/95 | N31: =SUM(F31:L31)-M31 -> 0 | O31: =IF(N31>10,10,ROUND(N31,0)) -> 0
A32: 17 | B32: T144231 | C32: LÊ | D32: MINH | E32: 15/08/96 | L32: 0.3 | N32: =SUM(F32:L32)-M32 -> 0.3 | O32: =IF(N32>10,10,ROUND(N32,0)) -> 0
A33: 18 | B33: T143150 | C33: NGÔ HỮU | D33: NHÂN | E33: 25/11/96 | N33: =SUM(F33:L33)-M33 -> 0 | O33: =IF(N33>10,10,ROUND(N33,0)) -> 0
A34: 19 | B34: T145448 | C34: CAO MINH | D34: NHẬT | E34: 25/12/96 | N34: =SUM(F34:L34)-M34 -> 0 | O34: =IF(N34>10,10,ROUND(N34,0)) -> 0
A35: 20 | B35: T143906 | C35: MAI HOÀNG | D35: PHÚC | E35: 24/01/96 | N35: =SUM(F35:L35)-M35 -> 0 | O35: =IF(N35>10,10,ROUND(N35,0)) -> 0
A36: 21 | B36: T143472 | C36: LIÊU HUY | D36: PHƯƠNG | E36: 02/06/96 | L36: 0.3 | N36: =SUM(F36:L36)-M36 -> 0.3 | O36: =IF(N36>10,10,ROUND(N36,0)) -> 0
A37: 22 | B37: T143666 | C37: VĂNG VĂN | D37: QUÍ | E37: 12/11/95 | N37: =SUM(F37:L37)-M37 -> 0 | O37: =IF(N37>10,10,ROUND(N37,0)) -> 0
A38: 23 | B38: T144564 | C38: CAO ANH | D38: QUỐC | E38: 16/03/96 | L38: 0.5 | N38: =SUM(F38:L38)-M38 -> 0.5 | O38: =IF(N38>10,10,ROUND(N38,0)) -> 1
A39: 24 | B39: T143649 | C39: NGUYỄN CÔNG | D39: SANG | E39: 20/11/96 | N39: =SUM(F39:L39)-M39 -> 0 | O39: =IF(N39>10,10,ROUND(N39,0)) -> 0
A40: 25 | B40: T143724 | C40: LƯU CAO | D40: SANG | E40: 08/04/96 | L40: 0.3 | N40: =SUM(F40:L40)-M40 -> 0.3 | O40: =IF(N40>10,10,ROUND(N40,0)) -> 0
A41: 26 | B41: T142974 | C41: LƯƠNG QUỐC | D41: THÁI | E41: 25/06/96 | L41: 0.2 | N41: =SUM(F41:L41)-M41 -> 0.2 | O41: =IF(N41>10,10,ROUND(N41,0)) -> 0
A42: 27 | B42: T145588 | C42: HUỲNH CÔNG | D42: THÀNH | E42: 29/10/96 | L42: 0.7 | N42: =SUM(F42:L42)-M42 -> 0.7 | O42: =IF(N42>10,10,ROUND(N42,0)) -> 1
...

Sheet SUMMARY (2)
A1: VAN LANG UNIVERSITY
A2: FACULTY OF INFORMATION TECHNOLOGY
A3: SUMMARY OF ACADEMIC TRANSCRIPT
A4: SEMESTER 02 (2015-2016)
A5: - Course Name : Database
A6: - Instructer Name : Ly Thi Huyen Chau | M6: K20T
A7: - Instructer Email : lythihuyenchau@vanlanguni.edu.vn
A8: - Location/Organization : VAN LANG University, Ho Chi Minh City, Viet Nam
A9: - Date of Course : Jan 2016
A10: - Duration : 15 weeks
A13: No | B13: ID | C13: FULL NAME | E13: DOB | F13: ATTENDANCE (5%) | G13: BONUS (5%) | H13: MIDTERM TEST (15%) | I13: ASSIGNMENT (15%) | J13: PRACTICE (20%) | K13: PROJECT (15%) | L13: THEORY TEST (25%) | M13: FINAL POINTS | N13: NOTE
A14: 1 | B14: T144296 | C14: NGUYỄN HOÀNG HOÀI | D14: ANH | E14: 24/01/96 | F14: =VLOOKUP(B14,#REF!,21,0) -> #REF! | G14: =VLOOKUP(B14,#REF!,21,0) -> #REF! | H14: 5 | I14: =VLOOKUP(B14,#REF!,30,0) -> #REF! | J14: =VLOOKUP(B14,#REF!,13,0) -> #REF! | K14: =VLOOKUP(B14,#REF!,16,0) -> #REF! | L14: =VLOOKUP(B14,#REF!,13,0) -> #REF! | M14: =(F14*0.05+G14*0.05+H14*0.15+I14*0.15+J14*0.2+K14*0.15+L14*0.25) -> #REF! | N14: =M14 -> #REF! | O14: =IF(N14<4.5,"Fail","") -> #REF! | P14: =IF(N14>=6.5,"CMU","") -> #REF!
A15: 2 | B15: T144647 | C15: LÊ THỊ DIỄM | D15: CA | E15: 28/02/96 | F15: =VLOOKUP(B15,#REF!,21,0) -> #REF! | G15: =VLOOKUP(B15,#REF!,21,0) -> #REF! | H15: 4 | I15: =VLOOKUP(B15,#REF!,30,0) -> #REF! | J15: =VLOOKUP(B15,#REF!,13,0) -> #REF! | K15: =VLOOKUP(B15,#REF!,16,0) -> #REF! | L15: =VLOOKUP(B15,#REF!,13,0) -> #REF! | M15: =(F15*0.05+G15*0.05+H15*0.15+I15*0.15+J15*0.2+K15*0.15+L15*0.25) -> #REF! | N15: =M15 -> #REF! | O15: =IF(N15<4.5,"Fail","") -> #REF! | P15: =IF(N15>=6.5,"CMU","") -> #REF!
A16: 3 | B16: T143054 | C16: PHẠM PHÚ | D16: CHƯƠNG | E16: 19/04/93 | F16: =VLOOKUP(B16,#REF!,21,0) -> #REF! | G16: =VLOOKUP(B16,#REF!,21,0) -> #REF! | H16: 7 | I16: =VLOOKUP(B16,#REF!,30,0) -> #REF! | J16: =VLOOKUP(B16,#REF!,13,0) -> #REF! | K16: =VLOOKUP(B16,#REF!,16,0) -> #REF! | L16: =VLOOKUP(B16,#REF!,13,0) -> #REF! | M16: =(F16*0.05+G16*0.05+H16*0.15+I16*0.15+J16*0.2+K16*0.15+L16*0.25) -> #REF! | N16: =M16 -> #REF! | O16: =IF(N16<4.5,"Fail","") -> #REF! | P16: =IF(N16>=6.5,"CMU","") -> #REF!
A17: 4 | B17: T137330 | C17: LÊ MINH | D17: ĐỨC | E17: 15/08/93 | F17: =VLOOKUP(B17,#REF!,21,0) -> #REF! | G17: =VLOOKUP(B17,#REF!,21,0) -> #REF! | H17: 5 | I17: =VLOOKUP(B17,#REF!,30,0) -> #REF! | J17: =VLOOKUP(B17,#REF!,13,0) -> #REF! | K17: =VLOOKUP(B17,#REF!,16,0) -> #REF! | L17: =VLOOKUP(B17,#REF!,13,0) -> #REF! | M17: =(F17*0.05+G17*0.05+H17*0.15+I17*0.15+J17*0.2+K17*0.15+L17*0.25) -> #REF! | N17: =M17 -> #REF! | O17: =IF(N17<4.5,"Fail","") -> #REF! | P17: =IF(N17>=6.5,"CMU","") -> #REF!
A18: 5 | B18: T144009 | C18: NGUYỄN ĐĂNG ĐẠI | D18: HIỆP | E18: 14/08/96 | F18: =VLOOKUP(B18,#REF!,21,0) -> #REF! | G18: =VLOOKUP(B18,#REF!,21,0) -> #REF! | H18: 1 | I18: =VLOOKUP(B18,#REF!,30,0) -> #REF! | J18: =VLOOKUP(B18,#REF!,13,0) -> #REF! | K18: =VLOOKUP(B18,#REF!,16,0) -> #REF! | L18: =VLOOKUP(B18,#REF!,13,0) -> #REF! | M18: =(F18*0.05+G18*0.05+H18*0.15+I18*0.15+J18*0.2+K18*0.15+L18*0.25) -> #REF! | N18: =M18 -> #REF! | O18: =IF(N18<4.5,"Fail","") -> #REF! | P18: =IF(N18>=6.5,"CMU","") -> #REF!
A19: 6 | B19: T146330 | C19: TRẦN TRUNG | D19: HIẾU | E19: 03/10/96 | F19: =VLOOKUP(B19,#REF!,21,0) -> #REF! | G19: =VLOOKUP(B19,#REF!,21,0) -> #REF! | H19: 0 | I19: =VLOOKUP(B19,#REF!,30,0) -> #REF! | J19: =VLOOKUP(B19,#REF!,13,0) -> #REF! | K19: =VLOOKUP(B19,#REF!,16,0) -> #REF! | L19: =VLOOKUP(B19,#REF!,13,0) -> #REF! | M19: =(F19*0.05+G19*0.05+H19*0.15+I19*0.15+J19*0.2+K19*0.15+L19*0.25) -> #REF! | N19: =M19 -> #REF! | O19: =IF(N19<4.5,"Fail","") -> #REF! | P19: =IF(N19>=6.5,"CMU","") -> #REF!
A20: 7 | B20: T143334 | C20: TRẦN TẤN | D20: HIẾU | E20: 22/08/96 | F20: =VLOOKUP(B20,#REF!,21,0) -> #REF! | G20: =VLOOKUP(B20,#REF!,21,0) -> #REF! | H20: 4 | I20: =VLOOKUP(B20,#REF!,30,0) -> #REF! | J20: =VLOOKUP(B20,#REF!,13,0) -> #REF! | K20: =VLOOKUP(B20,#REF!,16,0) -> #REF! | L20: =VLOOKUP(B20,'THEORY (2)'!$B$22:$O$67,13,0) -> 3.7 | M20: =(F20*0.05+G20*0.05+H20*0.15+I20*0.15+J20*0.2+K20*0.15+L20*0.25) -> #REF! | N20: =M20 -> #REF! | O20: =IF(N20<4.5,"Fail","") -> #REF! | P20: =IF(N20>=6.5,"CMU","") -> #REF!
A21: 8 | B21: T146150 | C21: DƯƠNG MINH | D21: HIẾU | E21: 31/03/96 | F21: =VLOOKUP(B21,#REF!,21,0) -> #REF! | G21: =VLOOKUP(B21,#REF!,21,0) -> #REF! | H21: 5 | I21: =VLOOKUP(B21,#REF!,30,0) -> #REF! | J21: =VLOOKUP(B21,#REF!,13,0) -> #REF! | K21: =VLOOKUP(B21,#REF!,16,0) -> #REF! | L21: =VLOOKUP(B21,'THEORY (2)'!$B$22:$O$67,13,0) -> 0.3 | M21: =(F21*0.05+G21*0.05+H21*0.15+I21*0.15+J21*0.2+K21*0.15+L21*0.25) -> #REF! | N21: =M21 -> #REF! | O21: =IF(N21<4.5,"Fail","") -> #REF! | P21: =IF(N21>=6.5,"CMU","") -> #REF!
A22: 9 | B22: T143639 | C22: HÀ NGỌC | D22: HƯNG | E22: 20/02/96 | F22: =VLOOKUP(B22,#REF!,21,0) -> #REF! | G22: =VLOOKUP(B22,#REF!,21,0) -> #REF! | H22: 5 | I22: =VLOOKUP(B22,#REF!,30,0) -> #REF! | J22: =VLOOKUP(B22,#REF!,13,0) -> #REF! | K22: =VLOOKUP(B22,#REF!,16,0) -> #REF! | L22: =VLOOKUP(B22,'THEORY (2)'!$B$22:$O$67,13,0) -> 0.3 | M22: =(F22*0.05+G22*0.05+H22*0.15+I22*0.15+J22*0.2+K22*0.15+L22*0.25) -> #REF! | N22: =M22 -> #REF! | O22: =IF(N22<4.5,"Fail","") -> #REF! | P22: =IF(N22>=6.5,"CMU","") -> #REF!
A23: 10 | B23: T143324 | C23: NGUYỄN CAO | D23: LÂM | E23: 02/05/96 | F23: =VLOOKUP(B23,#REF!,21,0) -> #REF! | G23: =VLOOKUP(B23,#REF!,21,0) -> #REF! | H23: 6 | I23: =VLOOKUP(B23,#REF!,30,0) -> #REF! | J23: =VLOOKUP(B23,#REF!,13,0) -> #REF! | K23: =VLOOKUP(B23,#REF!,16,0) -> #REF! | L23: =VLOOKUP(B23,'THEORY (2)'!$B$22:$O$67,13,0) -> 0 | M23: =(F23*0.05+G23*0.05+H23*0.15+I23*0.15+J23*0.2+K23*0.15+L23*0.25) -> #REF! | N23: =M23 -> #REF! | O23: =IF(N23<4.5,"Fail","") -> #REF! | P23: =IF(N23>=6.5,"CMU","") -> #REF!
A24: 11 | B24: T143662 | C24: THÂN DUY | D24: LINH | E24: 01/04/96 | F24: =VLOOKUP(B24,#REF!,21,0) -> #REF! | G24: =VLOOKUP(B24,#REF!,21,0) -> #REF! | H24: 5 | I24: =VLOOKUP(B24,#REF!,30,0) -> #REF! | J24: =VLOOKUP(B24,#REF!,13,0) -> #REF! | K24: =VLOOKUP(B24,#REF!,16,0) -> #REF! | L24: =VLOOKUP(B24,'THEORY (2)'!$B$22:$O$67,13,0) -> 0 | M24: =(F24*0.05+G24*0.05+H24*0.15+I24*0.15+J24*0.2+K24*0.15+L24*0.25) -> #REF! | N24: =M24 -> #REF! | O24: =IF(N24<4.5,"Fail","") -> #REF! | P24: =IF(N24>=6.5,"CMU","") -> #REF!
A25: 12 | B25: T140026 | C25: NGUYỄN VĂN ĐỨC | D25: LINH | E25: 13/09/94 | F25: =VLOOKUP(B25,#REF!,21,0) -> #REF! | G25: =VLOOKUP(B25,#REF!,21,0) -> #REF! | H25: 3 | I25: =VLOOKUP(B25,#REF!,30,0) -> #REF! | J25: =VLOOKUP(B25,#REF!,13,0) -> #REF! | K25: =VLOOKUP(B25,#REF!,16,0) -> #REF! | L25: =VLOOKUP(B25,'THEORY (2)'!$B$22:$O$67,13,0) -> 0 | M25: =(F25*0.05+G25*0.05+H25*0.15+I25*0.15+J25*0.2+K25*0.15+L25*0.25) -> #REF! | N25: =M25 -> #REF! | O25: =IF(N25<4.5,"Fail","") -> #REF! | P25: =IF(N25>=6.5,"CMU","") -> #REF!
A26: 13 | B26: T142772 | C26: MAI BÁ | D26: LỘC | E26: 02/01/96 | F26: =VLOOKUP(B26,#REF!,21,0) -> #REF! | G26: =VLOOKUP(B26,#REF!,21,0) -> #REF! | H26: 8 | I26: =VLOOKUP(B26,#REF!,30,0) -> #REF! | J26: =VLOOKUP(B26,#REF!,13,0) -> #REF! | K26: =VLOOKUP(B26,#REF!,16,0) -> #REF! | L26: =VLOOKUP(B26,'THEORY (2)'!$B$22:$O$67,13,0) -> 0 | M26: =(F26*0.05+G26*0.05+H26*0.15+I26*0.15+J26*0.2+K26*0.15+L26*0.25) -> #REF! | N26: =M26 -> #REF! | O26: =IF(N26<4.5,"Fail","") -> #REF! | P26: =IF(N26>=6.5,"CMU","") -> #REF!
A27: 14 | B27: T143407 | C27: NGUYỄN THANH | D27: LONG | E27: 28/04/96 | F27: =VLOOKUP(B27,#REF!,21,0) -> #REF! | G27: =VLOOKUP(B27,#REF!,21,0) -> #REF! | H27: 5 | I27: =VLOOKUP(B27,#REF!,30,0) -> #REF! | J27: =VLOOKUP(B27,#REF!,13,0) -> #REF! | K27: =VLOOKUP(B27,#REF!,16,0) -> #REF! | L27: =VLOOKUP(B27,'THEORY (2)'!$B$22:$O$67,13,0) -> 0 | M27: =(F27*0.05+G27*0.05+H27*0.15+I27*0.15+J27*0.2+K27*0.15+L27*0.25) -> #REF! | N27: =M27 -> #REF! | O27: =IF(N27<4.5,"Fail","") -> #REF! | P27: =IF(N27>=6.5,"CMU","") -> #REF!
A28: 15 | B28: T144054 | C28: NGUYỄN HỮU | D28: LUÂN | E28: 05/09/96 | F28: =VLOOKUP(B28,#REF!,21,0) -> #REF! | G28: =VLOOKUP(B28,#REF!,21,0) -> #REF! | H28: 6 | I28: =VLOOKUP(B28,#REF!,30,0) -> #REF! | J28: =VLOOKUP(B28,#REF!,13,0) -> #REF! | K28: =VLOOKUP(B28,#REF!,16,0) -> #REF! | L28: =VLOOKUP(B28,'THEORY (2)'!$B$22:$O$67,13,0) -> 0.3 | M28: =(F28*0.05+G28*0.05+H28*0.15+I28*0.15+J28*0.2+K28*0.15+L28*0.25) -> #REF! | N28: =M28 -> #REF! | O28: =IF(N28<4.5,"Fail","") -> #REF! | P28: =IF(N28>=6.5,"CMU","") -> #REF!
A29: 16 | B29: T145181 | C29: DƯƠNG THÀNH CÔNG | D29: LÝ | E29: 26/08/95 | F29: =VLOOKUP(B29,#REF!,21,0) -> #REF! | G29: =VLOOKUP(B29,#REF!,21,0) -> #REF! | H29: 4 | I29: =VLOOKUP(B29,#REF!,30,0) -> #REF! | J29: =VLOOKUP(B29,#REF!,13,0) -> #REF! | K29: =VLOOKUP(B29,#REF!,16,0) -> #REF! | L29: =VLOOKUP(B29,'THEORY (2)'!$B$22:$O$67,13,0) -> 0 | M29: =(F29*0.05+G29*0.05+H29*0.15+I29*0.15+J29*0.2+K29*0.15+L29*0.25) -> #REF! | N29: =M29 -> #REF! | O29: =IF(N29<4.5,"Fail","") -> #REF! | P29: =IF(N29>=6.5,"CMU","") -> #REF!
A30: 17 | B30: T144231 | C30: LÊ | D30: MINH | E30: 15/08/96 | F30: =VLOOKUP(B30,#REF!,21,0) -> #REF! | G30: =VLOOKUP(B30,#REF!,21,0) -> #REF! | H30: 7 | I30: =VLOOKUP(B30,#REF!,30,0) -> #REF! | J30: =VLOOKUP(B30,#REF!,13,0) -> #REF! | K30: =VLOOKUP(B30,#REF!,16,0) -> #REF! | L30: =VLOOKUP(B30,'THEORY (2)'!$B$22:$O$67,13,0) -> 0.3 | M30: =(F30*0.05+G30*0.05+H30*0.15+I30*0.15+J30*0.2+K30*0.15+L30*0.25) -> #REF! | N30: =M30 -> #REF! | O30: =IF(N30<4.5,"Fail","") -> #REF! | P30: =IF(N30>=6.5,"CMU","") -> #REF!
A31: 18 | B31: T143150 | C31: NGÔ HỮU | D31: NHÂN | E31: 25/11/96 | F31: =VLOOKUP(B31,#REF!,21,0) -> #REF! | G31: =VLOOKUP(B31,#REF!,21,0) -> #REF! | H31: 3 | I31: =VLOOKUP(B31,#REF!,30,0) -> #REF! | J31: =VLOOKUP(B31,#REF!,13,0) -> #REF! | K31: =VLOOKUP(B31,#REF!,16,0) -> #REF! | L31: =VLOOKUP(B31,'THEORY (2)'!$B$22:$O$67,13,0) -> 0 | M31: =(F31*0.05+G31*0.05+H31*0.15+I31*0.15+J31*0.2+K31*0.15+L31*0.25) -> #REF! | N31: =M31 -> #REF! | O31: =IF(N31<4.5,"Fail","") -> #REF! | P31: =IF(N31>=6.5,"CMU","") -> #REF!
... A56: 43 | B56: T143143 | C56: DƯƠNG TẤN | D56: VŨ | E56: 19/08/96 | F56: =VLOOKUP(B56,#REF!,21,0) -> #REF! | G56: =VLOOKUP(B56,#REF!,21,0) -> #REF! | H56: 4 | I56: =VLOOKUP(B56,#REF!,30,0) -> #REF! | J56: =VLOOKUP(B56,#REF!,13,0) -> #REF! | K56: =VLOOKUP(B56,#REF!,16,0) -> #REF! | L56: =VLOOKUP(B56,'THEORY (2)'!$B$22:$O$67,13,0) -> 0 | M56: =(F56*0.05+G56*0.05+H56*0.15+I56*0.15+J56*0.2+K56*0.15+L56*0.25) -> #REF! | N56: =M56 -> #REF! | O56: =IF(N56<4.5,"Fail","") -> #REF! | P56: =IF(N56>=6.5,"CMU","") -> #REF!
A57: 1 | B57: T103398 | C57: HUỲNH MINH | D57: ĐẠT | E57: 22/10/92 | F57: =VLOOKUP(B57,#REF!,21,0) -> #REF! | G57: =ROUND(SUM(#REF!,#REF!)/2,0) -> #REF! | H57: 0 | I57: =VLOOKUP(B57,#REF!,30,0) -> #REF! | J57: =VLOOKUP(B57,#REF!,13,0) -> #REF! | K57: =VLOOKUP(B57,#REF!,16,0) -> #REF! | L57: =VLOOKUP(B57,'THEORY (2)'!$B$22:$O$67,13,0) -> 0 | M57: =(F57*0.05+G57*0.05+H57*0.15+I57*0.15+J57*0.2+K57*0.15+L57*0.25) -> #REF! | N57: =M57 -> #REF! | O57: =IF(N57<4.5,"Fail","") -> #REF! | P57: =IF(N57>=6.5,"CMU","") -> #REF!
A58: 2 | B58: T137752 | C58: HUỲNH THỊ LIÊN | D58: HOÀN | E58: 15/10/93 | F58: =VLOOKUP(B58,#REF!,21,0) -> #REF! | G58: =ROUND(SUM(#REF!,#REF!)/2,0) -> #REF! | H58: 0 | I58: =VLOOKUP(B58,#REF!,30,0) -> #REF! | J58: =VLOOKUP(B58,#REF!,13,0) -> #REF! | K58: =VLOOKUP(B58,#REF!,16,0) -> #REF! | L58: =VLOOKUP(B58,'THEORY (2)'!$B$22:$O$67,13,0) -> 0 | M58: =(F58*0.05+G58*0.05+H58*0.15+I58*0.15+J58*0.2+K58*0.15+L58*0.25) -> #REF! | N58: =M58 -> #REF! | O58: =IF(N58<4.5,"Fail","") -> #REF! | P58: =IF(N58>=6.5,"CMU","") -> #REF!
A59: 3 | B59: T136105 | C59: NGUYỄN CAO | D59: HỌC | E59: 22/05/94 | F59: =VLOOKUP(B59,#REF!,21,0) -> #REF! | G59: =ROUND(SUM(#REF!,#REF!)/2,0) -> #REF! | H59: 0 | I59: =VLOOKUP(B59,#REF!,30,0) -> #REF! | J59: =VLOOKUP(B59,#REF!,13,0) -> #REF! | K59: =VLOOKUP(B59,#REF!,16,0) -> #REF! | L59: =VLOOKUP(B59,'THEORY (2)'!$B$22:$O$67,13,0) -> 0 | M59: =(F59*0.05+G59*0.05+H59*0.15+I59*0.15+J59*0.2+K59*0.15+L59*0.25) -> #REF! | N59: =M59 -> #REF! | O59: =IF(N59<4.5,"Fail","") -> #REF! | P59: =IF(N59>=6.5,"CMU","") -> #REF!
A60: 4 | B60: T137817 | C60: NGUYỄN TẤN | D60: HƯNG | E60: 30/08/94 | F60: =VLOOKUP(B60,#REF!,21,0) -> #REF! | G60: =ROUND(SUM(#REF!,#REF!)/2,0) -> #REF! | H60: 6 | I60: =VLOOKUP(B60,#REF!,30,0) -> #REF! | J60: =VLOOKUP(B60,#REF!,13,0) -> #REF! | K60: =VLOOKUP(B60,#REF!,16,0) -> #REF! | L60: =VLOOKUP(B60,'THEORY (2)'!$B$22:$O$67,13,0) -> 0.6 | M60: =(F60*0.05+G60*0.05+H60*0.15+I60*0.15+J60*0.2+K60*0.15+L60*0.25) -> #REF! | N60: =M60 -> #REF! | O60: =IF(N60<4.5,"Fail","") -> #REF! | P60: =IF(N60>=6.5,"CMU","") -> #REF!
A61: 5 | B61: K121881 | C61: PHAN VŨ | D61: HUY | E61: 31/10/94 | F61: =VLOOKUP(B61,#REF!,21,0) -> #REF! | G61: =ROUND(SUM(#REF!,#REF!)/2,0) -> #REF! | H61: 1 | I61: =VLOOKUP(B61,#REF!,30,0) -> #REF! | J61: =VLOOKUP(B61,#REF!,13,0) -> #REF! | K61: =VLOOKUP(B61,#REF!,16,0) -> #REF! | L61: =VLOOKUP(B61,'THEORY (2)'!$B$22:$O$67,13,0) -> 0 | M61: =(F61*0.05+G61*0.05+H61*0.15+I61*0.15+J61*0.2+K61*0.15+L61*0.25) -> #REF! | N61: =M61 -> #REF! | O61: =IF(N61<4.5,"Fail","") -> #REF! | P61: =IF(N61>=6.5,"CMU","") -> #REF!
A62: 6 | B62: T143663 | C62: VÕ CÔNG | D62: MINH | E62: 25/06/96 | F62: =VLOOKUP(B62,#REF!,21,0) -> #REF! | G62: =ROUND(SUM(#REF!,#REF!)/2,0) -> #REF! | H62: 5 | I62: =VLOOKUP(B62,#REF!,30,0) -> #REF! | J62: =VLOOKUP(B62,#REF!,13,0) -> #REF! | K62: =VLOOKUP(B62,#REF!,16,0) -> #REF! | L62: =VLOOKUP(B62,'THEORY (2)'!$B$22:$O$67,13,0) -> 0 | M62: =(F62*0.05+G62*0.05+H62*0.15+I62*0.15+J62*0.2+K62*0.15+L62*0.25) -> #REF! | N62: =M62 -> #REF! | O62: =IF(N62<4.5,"Fail","") -> #REF! | P62: =IF(N62>=6.5,"CMU","") -> #REF!
A63: 7 | B63: T123400 | C63: CAO TẤN | D63: PHÁT | E63: 09/07/93 | F63: =VLOOKUP(B63,#REF!,21,0) -> #REF! | G63: =ROUND(SUM(#REF!,#REF!)/2,0) -> #REF! | H63: 0 | I63: =VLOOKUP(B63,#REF!,30,0) -> #REF! | J63: =VLOOKUP(B63,#REF!,13,0) -> #REF! | K63: =VLOOKUP(B63,#REF!,16,0) -> #REF! | L63: =VLOOKUP(B63,'THEORY (2)'!$B$22:$O$67,13,0) -> 0 | M63: =(F63*0.05+G63*0.05+H63*0.15+I63*0.15+J63*0.2+K63*0.15+L63*0.25) -> #REF! | N63: =M63 -> #REF! | O63: =IF(N63<4.5,"Fail","") -> #REF!
A64: 8 | B64: T134306 | C64: ĐẶNG ĐỨC | D64: TIẾN | E64: 28/12/95 | F64: =VLOOKUP(B64,#REF!,21,0) -> #REF! | G64: =ROUND(SUM(#REF!,#REF!)/2,0) -> #REF! | H64: 0 | I64: =VLOOKUP(B64,#REF!,30,0) -> #REF! | J64: =VLOOKUP(B64,#REF!,13,0) -> #REF! | K64: =VLOOKUP(B64,#REF!,16,0) -> #REF! | L64: =VLOOKUP(B64,'THEORY (2)'!$B$22:$O$67,13,0) -> 0 | M64: =(F64*0.05+G64*0.05+H64*0.15+I64*0.15+J64*0.2+K64*0.15+L64*0.25) -> #REF! | N64: =M64 -> #REF! | O64: =IF(N64<4.5,"Fail","") -> #REF!
A65: 9 | B65: T131417 | C65: NGÔ VƯƠNG ĐỨC | D65: TRÍ | E65: 20/02/95 | F65: 0 | G65: =ROUND(SUM(#REF!,#REF!)/2,0) -> #REF! | H65: 4 | I65: =VLOOKUP(B65,#REF!,30,0) -> #REF! | J65: =VLOOKUP(B65,#REF!,13,0) -> #REF! | K65: =VLOOKUP(B65,#REF!,16,0) -> #REF! | L65: =VLOOKUP(B65,'THEORY (2)'!$B$22:$O$67,13,0) -> 0.9 | M65: =(F65*0.05+G65*0.05+H65*0.15+I65*0.15+J65*0.2+K65*0.15+L65*0.25) -> #REF! | N65: =M65 -> #REF! | O65: =IF(N65<4.5,"Fail","") -> #REF!
A66: 10 | B66: T126567 | C66: HUỲNH MINH | D66: TRÍ | E66: 02/11/94 | F66: 0 | G66: =ROUND(SUM(#REF!,#REF!)/2,0) -> #REF! | H66: 0 | I66: =VLOOKUP(B66,#REF!,30,0) -> #REF! | J66: =VLOOKUP(B66,#REF!,13,0) -> #REF! | K66: =VLOOKUP(B66,#REF!,16,0) -> #REF! | L66: =#REF! -> #REF! | M66: =(F66*0.05+G66*0.05+H66*0.15+I66*0.15+J66*0.2+K66*0.15+L66*0.25) -> #REF! | N66: =M66 -> #REF! | O66: =IF(N66<4.5,"Fail","") -> #REF!
...

Sheet Sheet1
A1: a | B1: b
A2: T145588 | B2: 5
A3: T143150 | B3: 7
A4: T145270 | B4: 8
A5: T140776 | B5: 8
A6: T144009 | B6: 5
A7: T143324 | B7: 8.5
A8: T144231 | B8: 8
A9: T144726 | B9: 7
A10: T144103 | B10: 8
A11: T143143 | B11: 9
A12: T145448 | B12: 8
A13: T144054 | B13: 7.5
... A41: T143666 | B41: 5
